### version information

```
migrateit version: 0.6.0
sys.version:
    3.13.3 (main, Apr  9 2025, 07:44:25) [GCC 14.2.1 20250207]
sys.executable: /media/data/Workspace/personal/richjet/venv/bin/python
os.name: posix
sys.platform: linux
```

### error information

```
An unexpected error has occurred: ValueError: Migration 0004_symbols.sql has a different hash in the database: found=559d20d9b797e314b47710127b7239d80a782f8d2c578fdde8a77923d042542d existing=e85a010fd4fc6c82d0f385e821edf2d08dce4d8a49039f23562214055f28b49b
```

```
Traceback (most recent call last):
  File "/media/data/Workspace/personal/richjet/venv/lib/python3.13/site-packages/migrateit/reporters/errors.py", line 22, in error_handler
    yield
  File "/media/data/Workspace/personal/richjet/venv/lib/python3.13/site-packages/migrateit/main.py", line 71, in main
    return commands.cmd_run(
           ~~~~~~~~~~~~~~~~^
        client,
        ^^^^^^^
    ...<2 lines>...
        is_hash_update=args.update_hash,
        ^^^^^^^^^^^^^^^^^^^^^^^^^^^^^^^^
    )
    ^
  File "/media/data/Workspace/personal/richjet/venv/lib/python3.13/site-packages/migrateit/cli.py", line 102, in cmd_run
    client.validate_migrations(statuses)
    ~~~~~~~~~~~~~~~~~~~~~~~~~~^^^^^^^^^^
  File "/media/data/Workspace/personal/richjet/venv/lib/python3.13/site-packages/migrateit/clients/psql.py", line 182, in validate_migrations
    raise ValueError(
    ...<2 lines>...
    )
ValueError: Migration 0004_symbols.sql has a different hash in the database: found=559d20d9b797e314b47710127b7239d80a782f8d2c578fdde8a77923d042542d existing=e85a010fd4fc6c82d0f385e821edf2d08dce4d8a49039f23562214055f28b49b
```
